Workbook

Sheet ReadMe
A1: Base de données — Réclamations DIRMOB
A2: Grand Paris Seine Ouest — Service Mobilité
A4: IDENTITÉ DU FICHIER
A5: Nom | B5: bdd_reclamations_dirmob.xlsx
A6: Version | B6: 1.0
A7: Date de création | B7: 21/04/2026
A8: Dernière mise à jour | B8: 21/04/2026
A9: Propriétaire (owner) | B9: DIRMOB — Grand Paris Seine Ouest
A10: Contact référent | B10: dirmob@agglo-gpso.fr
A11: Licence / usage | B11: Interne GPSO. Les référentiels externes (ref_lignes, ref_arrets, ref_prestataires) sont des communs numériques (Licence Ouverte Etalab 2.0).
A13: OBJET
A14: But | B14: Enregistrer et suivre les réclamations usagers sur les services de mobilité (bus, Vélib, IRVE, autopartage).
A15: Usage attendu | B15: Saisie quotidienne par les agents DIRMOB ; bilans mensuels/trimestriels ; remontées aux prestataires et aux élus.
A17: ARCHITECTURE
A18: Principe | B18: Modèle relationnel : une table par entité métier, liées entre elles par identifiants (IDs).
A19: Convention de nommage | B19: snake_case, sans accents, sans espaces, sans caractères spéciaux.
A20: Identifiants | B20: Tous les IDs sont non signifiants, uniques et stables dans le temps.
A23: CONTENU DU FICHIER (8 tables + 1 vue + 2 docs)
A24: Onglet | B24: Type | C24: Rôle | D24: Source | E24: Fréquence MAJ | F24: Responsable
A25: ReadMe | B25: Documentation | C25: Métadonnées globales du fichier | D25: Interne | E25: Ponctuelle | F25: DIRMOB
A26: Dict_donnees | B26: Documentation | C26: Dictionnaire de toutes les colonnes | D26: Interne | E26: À chaque évolution | F26: DIRMOB
A27: ref_lignes | B27: Référentiel externe | C27: Lignes de bus (commun IDFM) | D27: data.gouv.fr / IDFM | E27: Mensuelle | F27: IDFM (externe)
A28: ref_arrets | B28: Référentiel externe | C28: Arrêts de bus (commun IDFM) | D28: data.gouv.fr / IDFM | E28: Mensuelle | F28: IDFM (externe)
A29: ref_prestataires | B29: Référentiel externe | C29: Délégataires de service public | D29: DIRMOB + SIRENE | E29: Annuelle | F29: DIRMOB
A30: ref_motifs | B30: Référentiel interne | C30: Motifs de réclamation | D30: Interne DIRMOB | E30: Trimestrielle | F30: DIRMOB
A31: ref_statuts | B31: Référentiel interne | C31: Cycle de vie d'une réclamation | D31: Interne DIRMOB | E31: Rare | F31: DIRMOB
A32: ref_agents | B32: Référentiel interne | C32: Agents DIRMOB (traitement) | D32: RH GPSO | E32: À chaque arrivée/départ | F32: DIRMOB / RH
A33: reclamants | B33: Transactionnelle | C33: Personnes qui réclament | D33: Saisie agent | E33: Continue | F33: Agent saisie
A34: reclamations | B34: Transactionnelle | C34: Les réclamations (table principale) | D34: Saisie agent | E34: Continue | F34: Agent saisie
A35: suivi_reclamations | B35: Vue (tableau de suivi) | C35: Vue aplatie des réclamations (XLOOKUP) | D35: Dérivée de reclamations | E35: Automatique | F35: Auto
A38: HISTORIQUE DES VERSIONS
A39: Date | B39: Version | C39: Auteur | D39: Description
A40: 21/04/2026 | B40: 1.0 | C40: M. Andriamialison | D40: Création initiale dans le cadre de la formation BDD DIRMOB

Sheet Dict_donnees
A1: Dictionnaire de données
A2: Description formelle de chaque champ de chaque table — garantit la compréhension commune et la continuité de service.
A4: Table | B4: Champ | C4: Type | D4: Obligatoire | E4: Clé / Contrainte | F4: Description | G4: Valeurs possibles / Format | H4: Source | I4: Exemple
A5: ref_lignes | B5: id_ligne | C5: Texte | D5: Oui | E5: PK | F5: Identifiant unique de la ligne | G5: L + 3 chiffres | H5: IDFM | I5: L001
A6: ref_lignes | B6: numero | C6: Texte | D6: Oui | F6: Numéro commercial de la ligne | G6: Libre | H6: IDFM | I6: 389
A7: ref_lignes | B7: nom | C7: Texte | D7: Oui | F7: Dénomination de la ligne | G7: Libre | H7: IDFM | I7: Clamart - Issy
A8: ref_lignes | B8: id_prestataire | C8: Texte | D8: Oui | E8: FK ref_prestataires | F8: Prestataire exploitant | G8: Voir ref_prestataires | H8: DIRMOB | I8: P001
A9: ref_lignes | B9: date_import | C9: Date | D9: Oui | F9: Date d'import depuis la source | G9: JJ/MM/AAAA | H9: Auto | I9: 01/04/2026
A10: ref_arrets | B10: id_arret | C10: Texte | D10: Oui | E10: PK | F10: Identifiant unique de l'arrêt | G10: A + 3 chiffres | H10: IDFM | I10: A001
A11: ref_arrets | B11: nom | C11: Texte | D11: Oui | F11: Dénomination de l'arrêt | G11: Libre | H11: IDFM | I11: Pasteur
A12: ref_arrets | B12: id_ligne | C12: Texte | D12: Oui | E12: FK ref_lignes | F12: Ligne desservie | G12: Voir ref_lignes | H12: IDFM | I12: L001
A13: ref_arrets | B13: latitude | C13: Nombre | D13: Non | F13: Coordonnée géographique (WGS84) | G13: Décimal | H13: IDFM | I13: 48.8156
A14: ref_arrets | B14: longitude | C14: Nombre | D14: Non | F14: Coordonnée géographique (WGS84) | G14: Décimal | H14: IDFM | I14: 2.2500
A15: ref_prestataires | B15: id_prestataire | C15: Texte | D15: Oui | E15: PK | F15: Identifiant unique du prestataire | G15: P + 3 chiffres | H15: DIRMOB | I15: P001
A16: ref_prestataires | B16: nom | C16: Texte | D16: Oui | E16: UNIQUE | F16: Raison sociale | G16: Libre, sans variations | H16: DIRMOB | I16: Keolis
A17: ref_prestataires | B17: siret | C17: Texte | D17: Non | F17: Numéro SIRET | G17: 14 chiffres | H17: SIRENE | I17: 12345678901234
A18: ref_prestataires | B18: contact_email | C18: Texte | D18: Non | F18: Email de contact | G18: Email valide | H18: DIRMOB | I18: contact@keolis.fr
A19: ref_prestataires | B19: contact_tel | C19: Texte | D19: Non | F19: Téléphone de contact | G19: 10 chiffres | H19: DIRMOB | I19: 0123456789
A20: ref_motifs | B20: id_motif | C20: Texte | D20: Oui | E20: PK | F20: Identifiant du motif | G20: M + 2 chiffres | H20: DIRMOB | I20: M01
A21: ref_motifs | B21: libelle | C21: Texte | D21: Oui | E21: UNIQUE | F21: Libellé du motif | G21: Voir liste ref_motifs | H21: DIRMOB | I21: Retard
A22: ref_motifs | B22: categorie | C22: Texte | D22: Oui | F22: Famille de motif | G22: Ponctualité | Matériel | Confort | Service | Autre | H22: DIRMOB | I22: Ponctualité
A23: ref_statuts | B23: id_statut | C23: Texte | D23: Oui | E23: PK | F23: Identifiant du statut | G23: S + 1 chiffre | H23: DIRMOB | I23: S1
A24: ref_statuts | B24: libelle | C24: Texte | D24: Oui | E24: UNIQUE | F24: Libellé du statut | G24: Voir liste ref_statuts | H24: DIRMOB | I24: Ouverte
A25: ref_statuts | B25: ordre | C25: Nombre | D25: Oui | F25: Ordre logique dans le cycle de vie | G25: Entier 1-5 | H25: DIRMOB | I25: 1
A26: ref_agents | B26: id_agent | C26: Texte | D26: Oui | E26: PK | F26: Identifiant de l'agent | G26: A + 2 chiffres | H26: RH GPSO | I26: A01
A27: ref_agents | B27: nom | C27: Texte | D27: Oui | F27: Nom de famille (peut changer) | G27: Libre | H27: RH | I27: Martin
A28: ref_agents | B28: prenom | C28: Texte | D28: Oui | F28: Prénom | G28: Libre | H28: RH | I28: Sophie
A29: ref_agents | B29: email | C29: Texte | D29: Oui | E29: UNIQUE | F29: Email professionnel | G29: Email GPSO | H29: RH | I29: s.martin@gpso.fr
A30: reclamants | B30: id_reclamant | C30: Texte | D30: Oui | E30: PK | F30: Identifiant du réclamant (non signifiant) | G30: C + 3 chiffres | H30: Auto | I30: C001
A31: reclamants | B31: nom | C31: Texte | D31: Oui | F31: Nom de famille (peut changer : mariage) | G31: Libre | H31: Saisie | I31: Martin
A32: reclamants | B32: prenom | C32: Texte | D32: Oui | F32: Prénom | G32: Libre | H32: Saisie | I32: Jean
A33: reclamants | B33: email | C33: Texte | D33: Non | F33: Email (peut changer) | G33: Email valide | H33: Saisie | I33: j.martin@...fr
A34: reclamants | B34: telephone | C34: Texte | D34: Non | F34: Téléphone | G34: 10 chiffres | H34: Saisie | I34: 0612345678
A35: reclamants | B35: date_creation | C35: Date | D35: Oui | E35: DEFAULT = aujourd'hui | F35: Date de 1ère réclamation | G35: JJ/MM/AAAA | H35: Auto | I35: 05/03/2026
A36: reclamations | B36: id_reclamation | C36: Texte | D36: Oui | E36: PK | F36: Identifiant de la réclamation | G36: R + 3 chiffres | H36: Auto | I36: R001
A37: reclamations | B37: date_reclamation | C37: Date | D37: Oui | E37: NOT NULL | F37: Date de dépôt | G37: JJ/MM/AAAA | H37: Saisie | I37: 05/03/2026
A38: reclamations | B38: id_reclamant | C38: Texte | D38: Oui | E38: FK reclamants | F38: Qui réclame | G38: Voir reclamants | H38: Saisie | I38: C001
A39: reclamations | B39: id_ligne | C39: Texte | D39: Oui | E39: FK ref_lignes | F39: Ligne concernée | G39: Voir ref_lignes | H39: Saisie | I39: L001
A40: reclamations | B40: id_motif | C40: Texte | D40: Oui | E40: FK ref_motifs | F40: Motif principal | G40: Voir ref_motifs | H40: Saisie | I40: M01
A41: reclamations | B41: id_statut | C41: Texte | D41: Oui | E41: FK ref_statuts / DEFAULT = S1 | F41: Statut courant | G41: Voir ref_statuts | H41: Saisie / Auto | I41: S1
...

Sheet ref_lignes
A1: RÉFÉRENTIEL EXTERNE — Lignes de bus (source : IDFM, commun numérique)
A2: id_ligne | B2: numero | C2: nom | D2: id_prestataire | E2: date_import
A3: L001 | B3: 389 | C3: Clamart - Issy | D3: P001 | E3: 01/04/2026
A4: L002 | B4: 169 | C4: Pont de Sèvres - Place Balard | D4: P002 | E4: 01/04/2026
A5: L003 | B5: 160 | C5: Boulogne - Versailles | D5: P001 | E5: 01/04/2026
A6: L004 | B6: 467 | C6: Meudon - Sèvres | D6: P001 | E6: 01/04/2026
A7: L005 | B7: 179 | C7: Pont de Sèvres - Meudon | D7: P002 | E7: 01/04/2026
A8: L006 | B8: 291 | C8: Issy RER - Vanves | D8: P001 | E8: 01/04/2026
A9: L007 | B9: 189 | C9: Boulogne Pont de St Cloud - Porte de St Cloud | D9: P002 | E9: 01/04/2026
A10: L008 | B10: 126 | C10: Porte d'Orléans - Chaville Vélizy | D10: P002 | E10: 01/04/2026

Sheet ref_arrets
A1: RÉFÉRENTIEL EXTERNE — Arrêts (source : IDFM, commun numérique)
A2: id_arret | B2: nom | C2: id_ligne | D2: latitude | E2: longitude
A3: A001 | B3: Pasteur | C3: L001 | D3: 48.8156 | E3: 2.25
A4: A002 | B4: Mairie de Clamart | C4: L001 | D4: 48.8033 | E4: 2.2639
A5: A003 | B5: Porte d'Issy | C5: L001 | D5: 48.8283 | E5: 2.27
A6: A004 | B6: Pont de Sèvres | C6: L002 | D6: 48.8297 | E6: 2.2308
A7: A005 | B7: Place Balard | C7: L002 | D7: 48.8361 | E7: 2.2778
A8: A006 | B8: Meudon Val Fleury | C8: L004 | D8: 48.8122 | E8: 2.24
A9: A007 | B9: Sèvres Ville d'Avray | C9: L004 | D9: 48.8214 | E9: 2.2111
A10: A008 | B10: Chaville Vélizy | C10: L008 | D10: 48.8044 | E10: 2.1906

Sheet ref_prestataires
A1: RÉFÉRENTIEL — Prestataires / délégataires
A2: id_prestataire | B2: nom | C2: siret | D2: contact_email | E2: contact_tel
A3: P001 | B3: Keolis | C3: 55214482400013 | D3: contact@keolis.com | E3: 0176530000
A4: P002 | B4: RATP | C4: 77566343801906 | D4: contact@ratp.fr | E4: 0158780000
A5: P003 | B5: Transdev IDF | C5: 33293944000050 | D5: contact@transdev-idf.com | E5: 0130230000

Sheet ref_motifs
A1: RÉFÉRENTIEL INTERNE — Motifs de réclamation
A2: id_motif | B2: libelle | C2: categorie
A3: M01 | B3: Retard | C3: Ponctualité
A4: M02 | B4: Avance | C4: Ponctualité
A5: M03 | B5: Bus non passé | C5: Ponctualité
A6: M04 | B6: Panne matériel | C6: Matériel
A7: M05 | B7: Véhicule sale | C7: Confort
A8: M06 | B8: Climatisation défaillante | C8: Confort
A9: M07 | B9: Comportement conducteur | C9: Service
A10: M08 | B10: Information voyageurs | C10: Service
A11: M09 | B11: Accessibilité PMR | C11: Service
A12: M10 | B12: Autre | C12: Autre

Sheet ref_statuts
A1: RÉFÉRENTIEL INTERNE — Statuts (cycle de vie)
A2: id_statut | B2: libelle | C2: ordre
A3: S1 | B3: Ouverte | C3: 1
A4: S2 | B4: En cours | C4: 2
A5: S3 | B5: En attente prestataire | C5: 3
A6: S4 | B6: Close | C6: 4
A7: S5 | B7: Annulée | C7: 5

Sheet ref_agents
A1: RÉFÉRENTIEL INTERNE — Agents DIRMOB
A2: id_agent | B2: nom | C2: prenom | D2: email
A3: A01 | B3: Martin | C3: Sophie | D3: s.martin@gpso.fr
A4: A02 | B4: Dupont | C4: Paul | D4: p.dupont@gpso.fr
A5: A03 | B5: Nguyen | C5: Thi | D5: t.nguyen@gpso.fr
A6: A04 | B6: Roca | C6: Cristina | D6: c.roca@gpso.fr

Sheet reclamants
A1: TABLE TRANSACTIONNELLE — Réclamants (personnes qui réclament)
A2: id_reclamant | B2: nom | C2: prenom | D2: email | E2: telephone | F2: date_creation
A3: C001 | B3: Martin | C3: Jean | D3: j.martin@mail.fr | E3: 0612345678 | F3: 05/03/2026
A4: C002 | B4: Dupont | C4: Anne | D4: a.dupont@mail.fr | E4: 0698765432 | F4: 07/03/2026
A5: C003 | B5: Nguyen | C5: Tran | D5: t.nguyen@mail.fr | E5: 0611223344 | F5: 10/03/2026
A6: C004 | B6: Garcia | C6: Maria | D6: m.garcia@mail.fr | E6: 0655667788 | F6: 12/03/2026
A7: C005 | B7: Leroy | C7: Philippe | D7: p.leroy@mail.fr | E7: 0633445566 | F7: 15/03/2026
A8: C006 | B8: Ben Salem | C8: Karim | D8: k.bensalem@mail.fr | E8: 0677889900 | F8: 18/03/2026
A9: C007 | B9: Moreau | C9: Isabelle | D9: i.moreau@mail.fr | E9: 0644556677 | F9: 22/03/2026
A10: C008 | B10: Petit | C10: Antoine | D10: a.petit@mail.fr | E10: 0688990011 | F10: 25/03/2026

Sheet reclamations
A1: TABLE TRANSACTIONNELLE — Réclamations (table principale, uniquement des FK)
A2: id_reclamation | B2: date_reclamation | C2: id_reclamant | D2: id_ligne | E2: id_motif | F2: id_statut | G2: id_agent | H2: date_cloture | I2: description
A3: R001 | B3: 05/03/2026 | C3: C001 | D3: L001 | E3: M01 | F3: S4 | G3: A01 | H3: 12/03/2026 | I3: Bus de 8h12 passé 10 min en retard, usagère a raté son train.
A4: R002 | B4: 07/03/2026 | C4: C002 | D4: L003 | E4: M02 | F4: S4 | G4: A02 | H4: 15/03/2026 | I4: Bus passé 8 min en avance à l'arrêt Pasteur.
A5: R003 | B5: 10/03/2026 | C5: C003 | D5: L001 | E5: M04 | F5: S2 | G5: A01 | I5: Panne de climatisation signalée deux jours de suite.
A6: R004 | B6: 12/03/2026 | C6: C004 | D6: L004 | E6: M07 | F6: S3 | G6: A03 | I6: Conducteur peu courtois lors d'une demande d'info.
A7: R005 | B7: 15/03/2026 | C7: C005 | D7: L002 | E7: M01 | F7: S4 | G7: A02 | H7: 20/03/2026 | I7: Retard récurrent sur la ligne 169 le matin.
A8: R006 | B8: 18/03/2026 | C8: C006 | D8: L005 | E8: M08 | F8: S2 | G8: A04 | I8: Affichage voyageur défaillant à l'arrêt Meudon Val Fleury.
A9: R007 | B9: 20/03/2026 | C9: C001 | D9: L001 | E9: M03 | F9: S4 | G9: A01 | H9: 22/03/2026 | I9: Bus de 17h45 non passé. Déjà signalé la semaine dernière.
A10: R008 | B10: 22/03/2026 | C10: C007 | D10: L006 | E10: M09 | F10: S3 | G10: A03 | I10: Rampe PMR en panne sur la ligne 291.
A11: R009 | B11: 25/03/2026 | C11: C008 | D11: L007 | E11: M05 | F11: S4 | G11: A02 | H11: 28/03/2026 | I11: Bus très sale, intérieur non nettoyé.
A12: R010 | B12: 27/03/2026 | C12: C003 | D12: L001 | E12: M01 | F12: S1 | G12: A01 | I12: Retard récurrent matin.
A13: R011 | B13: 29/03/2026 | C13: C002 | D13: L003 | E13: M07 | F13: S2 | G13: A02 | I13: Problème de comportement signalé de nouveau.
A14: R012 | B14: 31/03/2026 | C14: C005 | D14: L008 | E14: M04 | F14: S3 | G14: A04 | I14: Panne mécanique en ligne.
A15: R013 | B15: 02/04/2026 | C15: C001 | D15: L001 | E15: M01 | F15: S1 | G15: A01 | I15: Retard à l'arrêt Porte d'Issy.
A16: R014 | B16: 05/04/2026 | C16: C004 | D16: L004 | E16: M06 | F16: S2 | G16: A03 | I16: Climatisation non fonctionnelle.
A17: R015 | B17: 08/04/2026 | C17: C006 | D17: L002 | E17: M10 | F17: S1 | G17: A01 | I17: Autre : demande d'info sur un changement de trajet.

Sheet suivi_reclamations
A1: TABLEAU DE SUIVI — Vue aplatie des réclamations
A2: Cette feuille NE stocke AUCUNE donnée : elle les reconstitue depuis la table 'reclamations' via des formules XLOOKUP (équivalent jointure). Si une donnée change dans une table source (ex. nom d'un réclamant), elle est automatiquement mise à jour ici.
A4: id_reclamation | B4: date | C4: réclamant | D4: email | E4: ligne (n°) | F4: nom ligne | G4: prestataire | H4: motif | I4: statut | J4: agent | K4: description
A5: =reclamations!A3 -> R001 | B5: =reclamations!B3 -> 05/03/2026 | C5: =IFERROR(VLOOKUP(reclamations!C3,reclamants!$A$3:$F$50,2,FALSE())&" "&VLOOKUP(reclamations!C3,reclamants!$A$3:$F$50,3,FALSE()),"?") -> Martin Jean | D5: =IFERROR(VLOOKUP(reclamations!C3,reclamants!$A$3:$F$50,4,FALSE()),"") -> j.martin@mail.fr | E5: =IFERROR(VLOOKUP(reclamations!D3,ref_lignes!$A$3:$E$50,2,FALSE()),"?") -> 389 | F5: =IFERROR(VLOOKUP(reclamations!D3,ref_lignes!$A$3:$E$50,3,FALSE()),"?") -> Clamart - Issy | G5: =IFERROR(VLOOKUP(VLOOKUP(reclamations!D3,ref_lignes!$A$3:$E$50,4,FALSE()),ref_prestataires!$A$3:$E$50,2,FALSE()),"?") -> Keolis | H5: =IFERROR(VLOOKUP(reclamations!E3,ref_motifs!$A$3:$C$50,2,FALSE()),"?") -> Retard | I5: =IFERROR(VLOOKUP(reclamations!F3,ref_statuts!$A$3:$C$50,2,FALSE()),"?") -> Close | J5: =IFERROR(VLOOKUP(reclamations!G3,ref_agents!$A$3:$D$50,3,FALSE())&" "&VLOOKUP(reclamations!G3,ref_agents!$A$3:$D$50,2,FALSE()),"?") -> Sophie Martin | K5: =reclamations!I3 -> Bus de 8h12 passé 10 min en retard, usagère a raté son train.
A6: =reclamations!A4 -> R002 | B6: =reclamations!B4 -> 07/03/2026 | C6: =IFERROR(VLOOKUP(reclamations!C4,reclamants!$A$3:$F$50,2,FALSE())&" "&VLOOKUP(reclamations!C4,reclamants!$A$3:$F$50,3,FALSE()),"?") -> Dupont Anne | D6: =IFERROR(VLOOKUP(reclamations!C4,reclamants!$A$3:$F$50,4,FALSE()),"") -> a.dupont@mail.fr | E6: =IFERROR(VLOOKUP(reclamations!D4,ref_lignes!$A$3:$E$50,2,FALSE()),"?") -> 160 | F6: =IFERROR(VLOOKUP(reclamations!D4,ref_lignes!$A$3:$E$50,3,FALSE()),"?") -> Boulogne - Versailles | G6: =IFERROR(VLOOKUP(VLOOKUP(reclamations!D4,ref_lignes!$A$3:$E$50,4,FALSE()),ref_prestataires!$A$3:$E$50,2,FALSE()),"?") -> Keolis | H6: =IFERROR(VLOOKUP(reclamations!E4,ref_motifs!$A$3:$C$50,2,FALSE()),"?") -> Avance | I6: =IFERROR(VLOOKUP(reclamations!F4,ref_statuts!$A$3:$C$50,2,FALSE()),"?") -> Close | J6: =IFERROR(VLOOKUP(reclamations!G4,ref_agents!$A$3:$D$50,3,FALSE())&" "&VLOOKUP(reclamations!G4,ref_agents!$A$3:$D$50,2,FALSE()),"?") -> Paul Dupont | K6: =reclamations!I4 -> Bus passé 8 min en avance à l'arrêt Pasteur.
A7: =reclamations!A5 -> R003 | B7: =reclamations!B5 -> 10/03/2026 | C7: =IFERROR(VLOOKUP(reclamations!C5,reclamants!$A$3:$F$50,2,FALSE())&" "&VLOOKUP(reclamations!C5,reclamants!$A$3:$F$50,3,FALSE()),"?") -> Nguyen Tran | D7: =IFERROR(VLOOKUP(reclamations!C5,reclamants!$A$3:$F$50,4,FALSE()),"") -> t.nguyen@mail.fr | E7: =IFERROR(VLOOKUP(reclamations!D5,ref_lignes!$A$3:$E$50,2,FALSE()),"?") -> 389 | F7: =IFERROR(VLOOKUP(reclamations!D5,ref_lignes!$A$3:$E$50,3,FALSE()),"?") -> Clamart - Issy | G7: =IFERROR(VLOOKUP(VLOOKUP(reclamations!D5,ref_lignes!$A$3:$E$50,4,FALSE()),ref_prestataires!$A$3:$E$50,2,FALSE()),"?") -> Keolis | H7: =IFERROR(VLOOKUP(reclamations!E5,ref_motifs!$A$3:$C$50,2,FALSE()),"?") -> Panne matériel | I7: =IFERROR(VLOOKUP(reclamations!F5,ref_statuts!$A$3:$C$50,2,FALSE()),"?") -> En cours | J7: =IFERROR(VLOOKUP(reclamations!G5,ref_agents!$A$3:$D$50,3,FALSE())&" "&VLOOKUP(reclamations!G5,ref_agents!$A$3:$D$50,2,FALSE()),"?") -> Sophie Martin | K7: =reclamations!I5 -> Panne de climatisation signalée deux jours de suite.
A8: =reclamations!A6 -> R004 | B8: =reclamations!B6 -> 12/03/2026 | C8: =IFERROR(VLOOKUP(reclamations!C6,reclamants!$A$3:$F$50,2,FALSE())&" "&VLOOKUP(reclamations!C6,reclamants!$A$3:$F$50,3,FALSE()),"?") -> Garcia Maria | D8: =IFERROR(VLOOKUP(reclamations!C6,reclamants!$A$3:$F$50,4,FALSE()),"") -> m.garcia@mail.fr | E8: =IFERROR(VLOOKUP(reclamations!D6,ref_lignes!$A$3:$E$50,2,FALSE()),"?") -> 467 | F8: =IFERROR(VLOOKUP(reclamations!D6,ref_lignes!$A$3:$E$50,3,FALSE()),"?") -> Meudon - Sèvres | G8: =IFERROR(VLOOKUP(VLOOKUP(reclamations!D6,ref_lignes!$A$3:$E$50,4,FALSE()),ref_prestataires!$A$3:$E$50,2,FALSE()),"?") -> Keolis | H8: =IFERROR(VLOOKUP(reclamations!E6,ref_motifs!$A$3:$C$50,2,FALSE()),"?") -> Comportement conducteur | I8: =IFERROR(VLOOKUP(reclamations!F6,ref_statuts!$A$3:$C$50,2,FALSE()),"?") -> En attente prestataire | J8: =IFERROR(VLOOKUP(reclamations!G6,ref_agents!$A$3:$D$50,3,FALSE())&" "&VLOOKUP(reclamations!G6,ref_agents!$A$3:$D$50,2,FALSE()),"?") -> Thi Nguyen | K8: =reclamations!I6 -> Conducteur peu courtois lors d'une demande d'info.
A9: =reclamations!A7 -> R005 | B9: =reclamations!B7 -> 15/03/2026 | C9: =IFERROR(VLOOKUP(reclamations!C7,reclamants!$A$3:$F$50,2,FALSE())&" "&VLOOKUP(reclamations!C7,reclamants!$A$3:$F$50,3,FALSE()),"?") -> Leroy Philippe | D9: =IFERROR(VLOOKUP(reclamations!C7,reclamants!$A$3:$F$50,4,FALSE()),"") -> p.leroy@mail.fr | E9: =IFERROR(VLOOKUP(reclamations!D7,ref_lignes!$A$3:$E$50,2,FALSE()),"?") -> 169 | F9: =IFERROR(VLOOKUP(reclamations!D7,ref_lignes!$A$3:$E$50,3,FALSE()),"?") -> Pont de Sèvres - Place Balard | G9: =IFERROR(VLOOKUP(VLOOKUP(reclamations!D7,ref_lignes!$A$3:$E$50,4,FALSE()),ref_prestataires!$A$3:$E$50,2,FALSE()),"?") -> RATP | H9: =IFERROR(VLOOKUP(reclamations!E7,ref_motifs!$A$3:$C$50,2,FALSE()),"?") -> Retard | I9: =IFERROR(VLOOKUP(reclamations!F7,ref_statuts!$A$3:$C$50,2,FALSE()),"?") -> Close | J9: =IFERROR(VLOOKUP(reclamations!G7,ref_agents!$A$3:$D$50,3,FALSE())&" "&VLOOKUP(reclamations!G7,ref_agents!$A$3:$D$50,2,FALSE()),"?") -> Paul Dupont | K9: =reclamations!I7 -> Retard récurrent sur la ligne 169 le matin.
A10: =reclamations!A8 -> R006 | B10: =reclamations!B8 -> 18/03/2026 | C10: =IFERROR(VLOOKUP(reclamations!C8,reclamants!$A$3:$F$50,2,FALSE())&" "&VLOOKUP(reclamations!C8,reclamants!$A$3:$F$50,3,FALSE()),"?") -> Ben Salem Karim | D10: =IFERROR(VLOOKUP(reclamations!C8,reclamants!$A$3:$F$50,4,FALSE()),"") -> k.bensalem@mail.fr | E10: =IFERROR(VLOOKUP(reclamations!D8,ref_lignes!$A$3:$E$50,2,FALSE()),"?") -> 179 | F10: =IFERROR(VLOOKUP(reclamations!D8,ref_lignes!$A$3:$E$50,3,FALSE()),"?") -> Pont de Sèvres - Meudon | G10: =IFERROR(VLOOKUP(VLOOKUP(reclamations!D8,ref_lignes!$A$3:$E$50,4,FALSE()),ref_prestataires!$A$3:$E$50,2,FALSE()),"?") -> RATP | H10: =IFERROR(VLOOKUP(reclamations!E8,ref_motifs!$A$3:$C$50,2,FALSE()),"?") -> Information voyageurs | I10: =IFERROR(VLOOKUP(reclamations!F8,ref_statuts!$A$3:$C$50,2,FALSE()),"?") -> En cours | J10: =IFERROR(VLOOKUP(reclamations!G8,ref_agents!$A$3:$D$50,3,FALSE())&" "&VLOOKUP(reclamations!G8,ref_agents!$A$3:$D$50,2,FALSE()),"?") -> Cristina Roca | K10: =reclamations!I8 -> Affichage voyageur défaillant à l'arrêt Meudon Val Fleury.
A11: =reclamations!A9 -> R007 | B11: =reclamations!B9 -> 20/03/2026 | C11: =IFERROR(VLOOKUP(reclamations!C9,reclamants!$A$3:$F$50,2,FALSE())&" "&VLOOKUP(reclamations!C9,reclamants!$A$3:$F$50,3,FALSE()),"?") -> Martin Jean | D11: =IFERROR(VLOOKUP(reclamations!C9,reclamants!$A$3:$F$50,4,FALSE()),"") -> j.martin@mail.fr | E11: =IFERROR(VLOOKUP(reclamations!D9,ref_lignes!$A$3:$E$50,2,FALSE()),"?") -> 389 | F11: =IFERROR(VLOOKUP(reclamations!D9,ref_lignes!$A$3:$E$50,3,FALSE()),"?") -> Clamart - Issy | G11: =IFERROR(VLOOKUP(VLOOKUP(reclamations!D9,ref_lignes!$A$3:$E$50,4,FALSE()),ref_prestataires!$A$3:$E$50,2,FALSE()),"?") -> Keolis | H11: =IFERROR(VLOOKUP(reclamations!E9,ref_motifs!$A$3:$C$50,2,FALSE()),"?") -> Bus non passé | I11: =IFERROR(VLOOKUP(reclamations!F9,ref_statuts!$A$3:$C$50,2,FALSE()),"?") -> Close | J11: =IFERROR(VLOOKUP(reclamations!G9,ref_agents!$A$3:$D$50,3,FALSE())&" "&VLOOKUP(reclamations!G9,ref_agents!$A$3:$D$50,2,FALSE()),"?") -> Sophie Martin | K11: =reclamations!I9 -> Bus de 17h45 non passé. Déjà signalé la semaine dernière.
A12: =reclamations!A10 -> R008 | B12: =reclamations!B10 -> 22/03/2026 | C12: =IFERROR(VLOOKUP(reclamations!C10,reclamants!$A$3:$F$50,2,FALSE())&" "&VLOOKUP(reclamations!C10,reclamants!$A$3:$F$50,3,FALSE()),"?") -> Moreau Isabelle | D12: =IFERROR(VLOOKUP(reclamations!C10,reclamants!$A$3:$F$50,4,FALSE()),"") -> i.moreau@mail.fr | E12: =IFERROR(VLOOKUP(reclamations!D10,ref_lignes!$A$3:$E$50,2,FALSE()),"?") -> 291 | F12: =IFERROR(VLOOKUP(reclamations!D10,ref_lignes!$A$3:$E$50,3,FALSE()),"?") -> Issy RER - Vanves | G12: =IFERROR(VLOOKUP(VLOOKUP(reclamations!D10,ref_lignes!$A$3:$E$50,4,FALSE()),ref_prestataires!$A$3:$E$50,2,FALSE()),"?") -> Keolis | H12: =IFERROR(VLOOKUP(reclamations!E10,ref_motifs!$A$3:$C$50,2,FALSE()),"?") -> Accessibilité PMR | I12: =IFERROR(VLOOKUP(reclamations!F10,ref_statuts!$A$3:$C$50,2,FALSE()),"?") -> En attente prestataire | J12: =IFERROR(VLOOKUP(reclamations!G10,ref_agents!$A$3:$D$50,3,FALSE())&" "&VLOOKUP(reclamations!G10,ref_agents!$A$3:$D$50,2,FALSE()),"?") -> Thi Nguyen | K12: =reclamations!I10 -> Rampe PMR en panne sur la ligne 291.
A13: =reclamations!A11 -> R009 | B13: =reclamations!B11 -> 25/03/2026 | C13: =IFERROR(VLOOKUP(reclamations!C11,reclamants!$A$3:$F$50,2,FALSE())&" "&VLOOKUP(reclamations!C11,reclamants!$A$3:$F$50,3,FALSE()),"?") -> Petit Antoine | D13: =IFERROR(VLOOKUP(reclamations!C11,reclamants!$A$3:$F$50,4,FALSE()),"") -> a.petit@mail.fr | E13: =IFERROR(VLOOKUP(reclamations!D11,ref_lignes!$A$3:$E$50,2,FALSE()),"?") -> 189 | F13: =IFERROR(VLOOKUP(reclamations!D11,ref_lignes!$A$3:$E$50,3,FALSE()),"?") -> Boulogne Pont de St Cloud - Porte de St Cloud | G13: =IFERROR(VLOOKUP(VLOOKUP(reclamations!D11,ref_lignes!$A$3:$E$50,4,FALSE()),ref_prestataires!$A$3:$E$50,2,FALSE()),"?") -> RATP | H13: =IFERROR(VLOOKUP(reclamations!E11,ref_motifs!$A$3:$C$50,2,FALSE()),"?") -> Véhicule sale | I13: =IFERROR(VLOOKUP(reclamations!F11,ref_statuts!$A$3:$C$50,2,FALSE()),"?") -> Close | J13: =IFERROR(VLOOKUP(reclamations!G11,ref_agents!$A$3:$D$50,3,FALSE())&" "&VLOOKUP(reclamations!G11,ref_agents!$A$3:$D$50,2,FALSE()),"?") -> Paul Dupont | K13: =reclamations!I11 -> Bus très sale, intérieur non nettoyé.
A14: =reclamations!A12 -> R010 | B14: =reclamations!B12 -> 27/03/2026 | C14: =IFERROR(VLOOKUP(reclamations!C12,reclamants!$A$3:$F$50,2,FALSE())&" "&VLOOKUP(reclamations!C12,reclamants!$A$3:$F$50,3,FALSE()),"?") -> Nguyen Tran | D14: =IFERROR(VLOOKUP(reclamations!C12,reclamants!$A$3:$F$50,4,FALSE()),"") -> t.nguyen@mail.fr | E14: =IFERROR(VLOOKUP(reclamations!D12,ref_lignes!$A$3:$E$50,2,FALSE()),"?") -> 389 | F14: =IFERROR(VLOOKUP(reclamations!D12,ref_lignes!$A$3:$E$50,3,FALSE()),"?") -> Clamart - Issy | G14: =IFERROR(VLOOKUP(VLOOKUP(reclamations!D12,ref_lignes!$A$3:$E$50,4,FALSE()),ref_prestataires!$A$3:$E$50,2,FALSE()),"?") -> Keolis | H14: =IFERROR(VLOOKUP(reclamations!E12,ref_motifs!$A$3:$C$50,2,FALSE()),"?") -> Retard | I14: =IFERROR(VLOOKUP(reclamations!F12,ref_statuts!$A$3:$C$50,2,FALSE()),"?") -> Ouverte | J14: =IFERROR(VLOOKUP(reclamations!G12,ref_agents!$A$3:$D$50,3,FALSE())&" "&VLOOKUP(reclamations!G12,ref_agents!$A$3:$D$50,2,FALSE()),"?") -> Sophie Martin | K14: =reclamations!I12 -> Retard récurrent matin.
A15: =reclamations!A13 -> R011 | B15: =reclamations!B13 -> 29/03/2026 | C15: =IFERROR(VLOOKUP(reclamations!C13,reclamants!$A$3:$F$50,2,FALSE())&" "&VLOOKUP(reclamations!C13,reclamants!$A$3:$F$50,3,FALSE()),"?") -> Dupont Anne | D15: =IFERROR(VLOOKUP(reclamations!C13,reclamants!$A$3:$F$50,4,FALSE()),"") -> a.dupont@mail.fr | E15: =IFERROR(VLOOKUP(reclamations!D13,ref_lignes!$A$3:$E$50,2,FALSE()),"?") -> 160 | F15: =IFERROR(VLOOKUP(reclamations!D13,ref_lignes!$A$3:$E$50,3,FALSE()),"?") -> Boulogne - Versailles | G15: =IFERROR(VLOOKUP(VLOOKUP(reclamations!D13,ref_lignes!$A$3:$E$50,4,FALSE()),ref_prestataires!$A$3:$E$50,2,FALSE()),"?") -> Keolis | H15: =IFERROR(VLOOKUP(reclamations!E13,ref_motifs!$A$3:$C$50,2,FALSE()),"?") -> Comportement conducteur | I15: =IFERROR(VLOOKUP(reclamations!F13,ref_statuts!$A$3:$C$50,2,FALSE()),"?") -> En cours | J15: =IFERROR(VLOOKUP(reclamations!G13,ref_agents!$A$3:$D$50,3,FALSE())&" "&VLOOKUP(reclamations!G13,ref_agents!$A$3:$D$50,2,FALSE()),"?") -> Paul Dupont | K15: =reclamations!I13 -> Problème de comportement signalé de nouveau.
A16: =reclamations!A14 -> R012 | B16: =reclamations!B14 -> 31/03/2026 | C16: =IFERROR(VLOOKUP(reclamations!C14,reclamants!$A$3:$F$50,2,FALSE())&" "&VLOOKUP(reclamations!C14,reclamants!$A$3:$F$50,3,FALSE()),"?") -> Leroy Philippe | D16: =IFERROR(VLOOKUP(reclamations!C14,reclamants!$A$3:$F$50,4,FALSE()),"") -> p.leroy@mail.fr | E16: =IFERROR(VLOOKUP(reclamations!D14,ref_lignes!$A$3:$E$50,2,FALSE()),"?") -> 126 | F16: =IFERROR(VLOOKUP(reclamations!D14,ref_lignes!$A$3:$E$50,3,FALSE()),"?") -> Porte d'Orléans - Chaville Vélizy | G16: =IFERROR(VLOOKUP(VLOOKUP(reclamations!D14,ref_lignes!$A$3:$E$50,4,FALSE()),ref_prestataires!$A$3:$E$50,2,FALSE()),"?") -> RATP | H16: =IFERROR(VLOOKUP(reclamations!E14,ref_motifs!$A$3:$C$50,2,FALSE()),"?") -> Panne matériel | I16: =IFERROR(VLOOKUP(reclamations!F14,ref_statuts!$A$3:$C$50,2,FALSE()),"?") -> En attente prestataire | J16: =IFERROR(VLOOKUP(reclamations!G14,ref_agents!$A$3:$D$50,3,FALSE())&" "&VLOOKUP(reclamations!G14,ref_agents!$A$3:$D$50,2,FALSE()),"?") -> Cristina Roca | K16: =reclamations!I14 -> Panne mécanique en ligne.
... A19: =reclamations!A17 -> R015 | B19: =reclamations!B17 -> 08/04/2026 | C19: =IFERROR(VLOOKUP(reclamations!C17,reclamants!$A$3:$F$50,2,FALSE())&" "&VLOOKUP(reclamations!C17,reclamants!$A$3:$F$50,3,FALSE()),"?") -> Ben Salem Karim | D19: =IFERROR(VLOOKUP(reclamations!C17,reclamants!$A$3:$F$50,4,FALSE()),"") -> k.bensalem@mail.fr | E19: =IFERROR(VLOOKUP(reclamations!D17,ref_lignes!$A$3:$E$50,2,FALSE()),"?") -> 169 | F19: =IFERROR(VLOOKUP(reclamations!D17,ref_lignes!$A$3:$E$50,3,FALSE()),"?") -> Pont de Sèvres - Place Balard | G19: =IFERROR(VLOOKUP(VLOOKUP(reclamations!D17,ref_lignes!$A$3:$E$50,4,FALSE()),ref_prestataires!$A$3:$E$50,2,FALSE()),"?") -> RATP | H19: =IFERROR(VLOOKUP(reclamations!E17,ref_motifs!$A$3:$C$50,2,FALSE()),"?") -> Autre | I19: =IFERROR(VLOOKUP(reclamations!F17,ref_statuts!$A$3:$C$50,2,FALSE()),"?") -> Ouverte | J19: =IFERROR(VLOOKUP(reclamations!G17,ref_agents!$A$3:$D$50,3,FALSE())&" "&VLOOKUP(reclamations!G17,ref_agents!$A$3:$D$50,2,FALSE()),"?") -> Sophie Martin | K19: =reclamations!I17 -> Autre : demande d'info sur un changement de trajet.
